testdata/real/corpus_msft_50k.txt
Add 16116348 0 100 310500
Add 16116658 0 100 310400
Add 16116704 0 100 310500
Add 16116752 0 100 310600
Add 16116815 0 100 310700
Add 16118193 0 100 310300
Cxl 16116815
Add 16118930 0 100 310200
Cxl 16116752
Add 16119035 0 100 310100
Cxl 16116704
Add 16119145 0 100 310000
Cxl 16116658
Add 16124823 1 100 308400
Add 16124830 1 100 308400
Add 16124842 1 100 308400
Add 16124846 1 100 309400
Add 16124853 1 100 309000
Add 16135101 1 300 309500
Add 16138350 1 1200 308600
Add 16143489 1 200 309200
Add 16143675 1 400 309100
Add 16143782 1 400 309000
Add 16143806 1 400 308900
Add 16145541 1 1200 308800
Add 16160020 0 6600 310000
Cxl 16116348
Add 16160123 0 100 310400
Add 16163114 0 1200 310100
Add 16163205 0 200 310300
Add 16163311 0 400 310400
Add 16163457 0 400 310500
Add 16163573 0 400 310600
Add 16165149 0 3000 310700
Add 16165291 0 200 310700
Add 16165298 0 200 310800
Add 16165325 0 3000 310800
Add 16166153 0 100 309700
Add 16166170 0 100 309800
Cxl 16118193
Add 16166187 0 100 309700
Add 16166225 1 100 309100
Cxl 16166153
Add 16167006 0 100 309700
Add 16168549 0 100 309700
Add 16168686 0 3000 310600
Add 16168723 1 200 309400
Add 16168807 0 200 310600
Add 16168919 1 200 309300
Cxl 16168723
Add 16169307 1 3000 308700
Add 16169370 1 200 308700
Add 16169383 1 200 308600
Add 16170086 1 200 309400
Add 16170087 1 1200 308900
Add 16177736 1 20 309300
Add 16189570 0 200 310200
Cxl 16168549
Cxl 16166187
Cxl 16167006
Cxl 16166170
Add 7326600 1 5 309900
Add 3581980 0 28 310000
Add 1368569 1 250 309800
Add 3906511 0 100 310000
Add 1370414 1 300 309800
Add 4743470 0 100 310000
Add 1375833 1 5 309800
Add 4745892 0 267 310000
Add 2177947 1 50 309800
Add 4748779 0 2111 310000
Add 1372100 1 100 309700
Add 4749881 0 1867 310000
Add 3559741 1 148 309700
Add 4751686 0 29 310000
Add 4887006 1 1 309700
Add 4752136 0 87 310000
Add 4887010 1 4 309700
Add 4752217 0 250 310000
Add 1376057 1 20 309600
Add 4754975 0 141 310000
Add 10426539 1 81 309600
Add 4756682 0 100 310000
Add 2119713 1 500 309500
Add 4756755 0 1008 310000
Add 3068695 1 1575 309500
Add 4768364 0 889 310000
Add 3559825 1 65 309500
Add 4885371 0 14 310000
Add 3562160 1 20 309500
Add 4885495 0 2700 310000
Add 4291931 1 5000 309500
Add 4886246 0 120 310000
Add 5980674 1 1 309500
Add 4886247 0 700 310000
Add 5980676 1 200 309500
Add 4886471 0 46 310000
Add 2140005 1 30 309400
Add 4886998 0 200 310000
Add 4887141 0 170 310000
Add 4887302 0 100 310000
Add 5980692 0 200 310000
Add 5980693 0 50 310000
Add 5980695 0 499 310000
Add 5980697 0 154 310000
Add 5980698 0 250 310000
Add 5980699 0 100 310000
Add 5980702 0 100 310000
Add 5980703 0 200 310000
Add 5980704 0 130 310000
Add 5980708 0 150 310000
Add 5980709 0 202 310000
Add 5980710 0 1000 310000
Add 5980712 0 1000 310000
Add 6016695 0 216 310000
Add 7552907 0 300 310000
Add 8589322 0 5500 310000
Add 9940243 0 2000 310000
Add 10030243 0 200 310000
Add 10562940 0 100 310000
Add 12644416 0 200 310000
Add 12687322 0 1100 310000
Add 12921845 0 150 310000
Add 12991178 0 100 310000
Add 1379744 0 199 310100
Add 1507949 0 2000 310200
Add 1370494 0 225 310400
Add 1490846 0 5111 310400
Add 1903560 0 901 310400
Add 3097339 0 30 310400
Add 5980715 0 100 310400
Add 1287643 0 646 310500
Add 1360094 0 134 310500
Add 1366961 0 1000 310500
Add 1368847 0 5250 310500
Add 1570011 0 1911 310500
Add 1903443 0 112 310500
Add 1903525 0 200 310500
Add 1903563 0 1200 310500
Add 1903605 0 100 310500
Add 1903613 0 30 310500
Add 1903694 0 100 310500
Add 2123076 0 31 310500
Add 2131535 0 100 310500
Add 3553084 0 1368 310500
Add 4871000 0 70 310500
Add 5980719 0 190 310500
Add 5980723 0 100 310500
Add 5980725 0 100 310500
Add 7139837 0 220 310500
Add 1360097 0 2000 310600
Add 16190507 0 100 310300
Cxl 16160123
Add 16190527 0 100 310500
Cxl 16166225
Add 16190529 1 100 309200
Add 16190540 1 100 309600
Cxl 7326600
Add 16190566 1 100 309700
Cxl 16190527
Add 16190585 0 100 310600
Cxl 16190507
Add 16190592 0 100 309900
Mod 1368569 200 309800
Add 16190619 0 100 309900
Mod 1368569 5 309800
Mod 16168686 1200 310600
Cxl 16163114
Add 16190770 0 1200 310000
Cxl 16168807
Add 16190991 0 1200 310100
Add 16191105 0 3000 310200
Add 16191192 0 200 310200
Add 16191200 0 200 310300
Add 16191212 0 200 310400
Add 16191224 0 200 310500
Add 16191239 0 200 310600
Cxl 16190592
Cxl 16190619
Cxl 16190991
Cxl 16191105
Cxl 16190770
Cxl 16191192
Add 16191916 0 200 310900
Cxl 16191200
Cxl 16191212
Cxl 16191224
Cxl 16191239
Add 16191972 1 1200 309400
Add 16191973 0 3000 310300
Add 16192000 0 1200 310100
Mod 16163311 200 310400
Add 16192040 0 1200 310000
Add 16192061 0 200 310300
Cxl 16189570
Add 16192071 0 200 310400
Add 16192078 0 200 310500
Add 16192085 0 200 310600
Add 16192198 1 3000 309300
Add 16192215 0 3000 310200
Cxl 3581980
Cxl 3906511
Cxl 4743470
Cxl 4745892
Mod 4748779 1906 310000
Add 16192237 0 200 310200
Add 16192280 1 200 309300
Add 16192285 1 200 309200
Add 16192297 1 200 309100
Add 16192308 1 200 309000
Add 16192310 1 200 308900
Cxl 16191916
Add 16192331 0 200 310200
Add 16192365 1 3000 309200
Add 16192566 1 100 309600
Mod 16192198 1200 309300
Cxl 16192280
Cxl 16192566
Add 16192945 0 100 309900
Add 16192966 0 100 309900
Add 16193263 1 200 309700
Cxl 1368569
Mod 1370414 205 309800
Cxl 16193263
Cxl 16190529
Add 16194607 1 100 309300
Cxl 16192945
Add 16197394 1 100 309800
Mod 1370414 105 309800
Mod 16192966 28 309900
Add 16199225 1 100 309800
Cxl 16197394
Mod 1370414 5 309800
Add 16200228 0 100 309900
Cxl 16135101
Cxl 1370414
Cxl 1375833
Cxl 2177947
Cxl 16199225
Cxl 16200228
Add 16203672 1 300 309500
Cxl 16192966
Add 16207189 1 17 309600
Add 16224419 1 100 309700
Cxl 16192040
Cxl 16192237
Add 16238323 1 43 309400
Add 16248287 0 100 310000
Add 16256772 1 200 309500
Mod 4748779 1206 310000
Mod 4748779 1134 310000
Add 16269371 1 100 309500
Add 16271908 1 200 309600
Cxl 4748779
Mod 4749881 1001 310000
Add 16288197 0 33 310000
Cxl 16271908
Cxl 16288197
Add 16292948 0 33 309900
Add 16292963 0 100 309900
Cxl 16292948
Cxl 16292963
Add 16298656 1 267 309800
Add 16298663 1 3000 309800
Add 16298681 1 100 309800
Cxl 16224419
Add 16298686 1 100 309800
Cxl 16298681
Add 16298690 1 100 309800
Cxl 16298690
Cxl 16298686
Add 16298714 1 100 309800
Add 16299435 0 100 310100
Cxl 16298656
Cxl 16298663
Add 16317947 1 3000 309800
Add 16319638 0 100 310100
Cxl 4749881
Cxl 4751686
Cxl 4752136
Cxl 4752217
Cxl 4754975
Cxl 4756682
Mod 4756755 616 310000
Add 16323003 0 400 310000
Cxl 16323003
Cxl 4756755
Cxl 4768364
Cxl 4885371
Mod 4885495 1069 310000
Cxl 16203672
Add 16332196 0 300 310200
Cxl 16317947
Add 16333185 1 300 309900
Add 16333190 1 100 309900
Cxl 16298714
Add 16333290 1 200 309600
Add 16338595 1 9 309900
Add 13773845 1 300 309400
Add 5980729 0 550 310600
Add 1368403 1 3 309300
Add 11474422 0 1000 310600
Add 1379717 1 113 309300
Add 1477997 0 200 310700
Add 2114014 1 15 309300
Add 1579706 0 600 310700
Add 2177965 1 18 309300
Add 4886714 0 200 310700
Add 3552998 1 100 309300
Add 11673189 0 600 310700
Add 3735699 1 45 309300
Add 2114017 0 51 310800
Add 4862259 1 25 309300
Add 2180591 0 2000 310800
Add 4885670 1 9 309300
Add 3096844 0 100 310800
Add 5980680 1 200 309300
Add 8782215 0 340 310800
Add 5980681 1 1000 309300
Add 1500599 0 5556 310900
Add 5980682 1 100 309300
Add 1902422 0 1000 310900
Add 5980683 1 325 309300
Add 1903553 0 300 310900
Add 11333711 1 6 309300
Add 3560462 0 100 310900
Add 13429066 1 83 309300
Add 4885958 1 16 309100
Add 1360230 1 50 309000
Add 3065693 1 115 309000
Add 3199415 1 200 309000
Add 3528468 1 600 309000
Add 3554119 1 500 309000
Add 4338455 1 100 309000
Add 4886395 1 1000 309000
Add 11372724 1 2 309000
Mod 16333185 200 309900
Cxl 16333185
Cxl 16338595
Add 16364382 0 300 310300
Add 16364678 0 300 310400
Add 16365900 1 300 309900
Cxl 16333190
Cxl 16365900
Add 16387882 0 3000 310000
Add 16387886 0 100 310000
Add 16387891 0 3000 310000
Add 16387892 0 100 310000
Cxl 16387891
Cxl 16387892
Cxl 16333290
Cxl 16256772
Add 16388500 0 3000 310000
Add 16388505 0 100 310000
Cxl 16388500
Cxl 16388505
Mod 4885495 569 310000
Add 16391936 0 200 310100
