testdata/real/corpus_msft_50k.golden
replay v1 50000 183 24915 963 24122 0
fill 0 19614325 16165298 310800 100 buy
fill 1 19614327 16165298 310800 100 buy
fill 2 19727883 16692620 310900 100 buy
fill 3 19727887 16692620 310900 100 buy
fill 4 19728552 16712678 311000 100 buy
fill 5 19728553 16712678 311000 300 buy
fill 6 22488574 19476869 310200 200 sell
fill 7 22488576 21624536 310200 400 sell
fill 8 22488577 21624536 310200 100 sell
fill 9 22488578 21624536 310200 300 sell
fill 10 22488579 21624536 310200 200 sell
fill 11 22488581 21624536 310200 100 sell
fill 12 22488582 21624536 310200 100 sell
fill 13 22488584 21986397 310200 200 sell
fill 14 22493152 19341143 310100 200 sell
fill 15 22493152 19446319 310100 700 sell
fill 16 22493153 19446319 310100 100 sell
fill 17 22493154 19446319 310100 200 sell
fill 18 22493156 19446319 310100 100 sell
fill 19 22493159 19446319 310100 100 sell
fill 20 22493159 19504668 310100 128 sell
fill 21 22493160 19504668 310100 72 sell
fill 22 22493160 21992943 310100 200 sell
fill 23 22574319 18981415 310000 100 sell
fill 24 22574319 19259832 310000 200 sell
fill 25 22574319 19341386 310000 100 sell
fill 26 22574321 19341386 310000 200 sell
fill 27 22574322 19341386 310000 100 sell
fill 28 22574323 19341386 310000 100 sell
fill 29 22574325 19341386 310000 100 sell
fill 30 22574327 19341386 310000 600 sell
fill 31 22574327 19695041 310000 200 sell
fill 32 22574327 21884823 310000 200 sell
fill 33 22579078 19258914 309900 200 sell
fill 34 22579078 19259980 309900 800 sell
fill 35 22579079 19259980 309900 200 sell
fill 36 22579080 19259980 309900 200 sell
fill 37 22579080 21155127 309900 100 sell
fill 38 22579081 21155127 309900 200 sell
fill 39 22579082 21155127 309900 100 sell
fill 40 22581648 18993925 309800 200 sell
fill 41 22581648 19259153 309800 800 sell
fill 42 22581650 19259153 309800 100 sell
fill 43 22581651 19259153 309800 300 sell
fill 44 22582641 17254069 309700 200 sell
fill 45 22582641 18994033 309700 100 sell
fill 46 22582643 18994033 309700 200 sell
fill 47 22582644 18994033 309700 100 sell
fill 48 22582645 18994033 309700 800 sell
fill 49 22582645 19279171 309700 200 sell
fill 50 22582726 17254711 309600 200 sell
fill 51 22582726 18994041 309600 800 sell
fill 52 22582728 18994041 309600 100 sell
fill 53 22582730 18994041 309600 300 sell
fill 54 24609447 22508290 310600 200 buy
fill 55 24771559 22479339 310700 100 buy
fill 56 24771571 22479339 310700 100 buy
fill 57 24771572 22493318 310700 200 buy
fill 58 24840911 22306250 310800 100 buy
fill 59 24840911 22306449 310800 60 buy
fill 60 24840914 22306449 310800 140 buy
fill 61 24840914 22326197 310800 60 buy
fill 62 24840915 22326197 310800 100 buy
fill 63 24840916 22326197 310800 140 buy
fill 64 24840916 22479488 310800 160 buy
fill 65 24840918 22479488 310800 500 buy
fill 66 24840919 22479488 310800 102 buy
fill 67 24840920 22479488 310800 200 buy
fill 68 24840921 22479488 310800 200 buy
fill 69 24840925 22479488 310800 38 buy
fill 70 24840925 22486345 310800 162 buy
fill 71 24840926 22486345 310800 38 buy
fill 72 24840926 22490952 310800 162 buy
fill 73 24840927 22490952 310800 138 buy
fill 74 24840927 22562214 310800 62 buy
fill 75 24840928 22562214 310800 200 buy
fill 76 24840930 22562214 310800 38 buy
fill 77 28481748 23132823 309700 200 sell
fill 78 28481748 23195406 309700 800 sell
fill 79 28481753 23195406 309700 200 sell
fill 80 28481757 23195406 309700 200 sell
fill 81 28481757 23425804 309700 100 sell
fill 82 28481757 24771551 309700 200 sell
fill 83 28491645 23132759 309600 200 sell
fill 84 28491645 23132893 309600 700 sell
fill 85 28491647 23132893 309600 500 sell
fill 86 28491647 23132906 309600 300 sell
fill 87 28491648 23132906 309600 16 sell
fill 88 28491650 23132906 309600 34 sell
fill 89 28491650 24572043 309600 166 sell
fill 90 28491651 24572043 309600 34 sell
fill 91 28499159 17115856 309500 200 sell
fill 92 28499159 17116044 309500 1200 sell
fill 93 28499159 22654141 309500 700 sell
fill 94 28499161 22654141 309500 500 sell
fill 95 28499161 22791238 309500 200 sell
fill 96 28499161 24151030 309500 200 sell
fill 97 28499161 24553422 309500 200 sell
fill 98 28504840 16238323 309400 43 sell
fill 99 28504840 13773845 309400 300 sell
fill 100 28504840 16818635 309400 200 sell
fill 101 28504840 16818870 309400 457 sell
fill 102 28504841 16818870 309400 600 sell
fill 103 28504842 16818870 309400 143 sell
fill 104 28504842 17733307 309400 200 sell
fill 105 28504842 22654128 309400 200 sell
fill 106 28504842 22654173 309400 857 sell
fill 107 28504843 22654173 309400 343 sell
fill 108 28504843 23698125 309400 200 sell
fill 109 28504843 24519948 309400 200 sell
fill 110 28504843 25240569 309400 200 sell
fill 111 28532751 16168919 309300 200 sell
fill 112 28532751 16192198 309300 800 sell
fill 113 28532752 16192198 309300 400 sell
fill 114 28532752 3735699 309300 45 sell
fill 115 28532752 17733309 309300 200 sell
fill 116 28532752 19241482 309300 155 sell
fill 117 28532753 19241482 309300 45 sell
fill 118 28532753 22515922 309300 955 sell
fill 119 28532755 22515922 309300 245 sell
fill 120 28532755 22579097 309300 200 sell
fill 121 28532755 23377020 309300 100 sell
fill 122 28532755 23437589 309300 147 sell
fill 123 28532757 23437589 309300 53 sell
fill 124 29163563 16143489 309200 200 sell
fill 125 29163563 16192365 309200 600 sell
fill 126 29163564 16192365 309200 500 sell
fill 127 29163565 16192365 309200 100 sell
fill 128 29163565 22582734 309200 900 sell
fill 129 29163566 22582734 309200 200 sell
fill 130 29163567 22582734 309200 100 sell
fill 131 29163568 22582573 309200 200 sell
fill 132 29163992 16143675 309100 400 sell
fill 133 29163992 16407595 309100 600 sell
fill 134 29163994 16407595 309100 200 sell
fill 135 29163997 16407595 309100 300 sell
fill 136 29163998 16407595 309100 200 sell
fill 137 29163999 16407595 309100 16 sell
fill 138 29164000 16407595 309100 200 sell
fill 139 29164001 16407595 309100 600 sell
fill 140 29164002 16407595 309100 300 sell
fill 141 29164003 16407595 309100 200 sell
fill 142 29164004 16407595 309100 200 sell
fill 143 29164006 16407595 309100 184 sell
fill 144 29164006 22582679 309100 116 sell
fill 145 29164007 22582679 309100 284 sell
fill 146 29164007 22582831 309100 416 sell
fill 147 29164008 22582831 309100 200 sell
fill 148 29164009 22582831 309100 200 sell
fill 149 29164010 22582831 309100 200 sell
fill 150 29164011 22582831 309100 174 sell
fill 151 29164012 22582831 309100 200 sell
fill 152 29164013 22582831 309100 100 sell
fill 153 29164015 22582831 309100 200 sell
fill 154 29164016 22582831 309100 100 sell
fill 155 29164017 22582831 309100 300 sell
fill 156 29164020 22582831 309100 300 sell
fill 157 29164042 22582831 309100 333 sell
fill 158 29164048 22582831 309100 277 sell
fill 159 29164765 16124853 309000 100 sell
fill 160 29164765 16143782 309000 151 sell
fill 161 29164766 16143782 309000 249 sell
fill 162 29164766 17254234 309000 200 sell
fill 163 29164766 22592836 309000 351 sell
fill 164 29164767 22592836 309000 49 sell
fill 165 29164767 23287298 309000 200 sell
fill 166 31771498 28382238 310000 100 buy
fill 167 31818441 27701121 310100 300 buy
fill 168 31818443 27701121 310100 100 buy
fill 169 31818443 27701194 310100 200 buy
fill 170 31818443 28382223 310100 300 buy
fill 171 31818445 28382223 310100 200 buy
fill 172 31818446 28382223 310100 600 buy
fill 173 31818447 28382223 310100 100 buy
fill 174 31818447 29163617 310100 100 buy
fill 175 31818448 29163757 310100 200 buy
fill 176 38940712 29292964 309100 300 sell
fill 177 38940712 29372016 309100 100 sell
fill 178 38968016 29176830 309000 300 sell
fill 179 38968016 29292974 309000 100 sell
fill 180 38968018 29292974 309000 300 sell
fill 181 38968018 29292992 309000 100 sell
fill 182 38968018 29293055 309000 200 sell
level buy 308100 1300 5 29164604:200,29286660:100,38944784:400,38947434:200,38968052:400
level buy 308200 3200 6 29371928:200,38937394:200,38940713:1000,38941328:700,38941333:700,38968004:400
level buy 308300 800 3 29373353:200,38937392:200,38940760:400
level buy 308400 7117 17 16124823:100,16124830:100,16124842:100,28535465:200,29164811:2500,29286662:100,37180380:200,37181226:100,37181242:200,38407908:400,38493996:200,38891063:400,38937391:200,38944836:1000,38944837:1000,38968098:200,38968100:117
